[2022-06-20 06:41:16,944] {taskinstance.py:1159} INFO - Dependencies all met for <TaskInstance: dags_new_version.processing_user manual__2022-06-20T06:40:52.621468+00:00 [queued]>
[2022-06-20 06:41:17,080] {taskinstance.py:1159} INFO - Dependencies all met for <TaskInstance: dags_new_version.processing_user manual__2022-06-20T06:40:52.621468+00:00 [queued]>
[2022-06-20 06:41:17,085] {taskinstance.py:1356} INFO - 
--------------------------------------------------------------------------------
[2022-06-20 06:41:17,095] {taskinstance.py:1357} INFO - Starting attempt 1 of 2
[2022-06-20 06:41:17,096] {taskinstance.py:1358} INFO - 
--------------------------------------------------------------------------------
[2022-06-20 06:41:17,204] {taskinstance.py:1377} INFO - Executing <Task(PythonOperator): processing_user> on 2022-06-20 06:40:52.621468+00:00
[2022-06-20 06:41:17,343] {standard_task_runner.py:52} INFO - Started process 388 to run task
[2022-06-20 06:41:17,492] {standard_task_runner.py:79} INFO - Running: ['***', 'tasks', 'run', 'dags_new_version', 'processing_user', 'manual__2022-06-20T06:40:52.621468+00:00', '--job-id', '186', '--raw', '--subdir', 'DAGS_FOLDER/user.py', '--cfg-path', '/tmp/tmpd304s1_h', '--error-file', '/tmp/tmp0ulyiojt']
[2022-06-20 06:41:17,533] {standard_task_runner.py:80} INFO - Job 186: Subtask processing_user
[2022-06-20 06:41:19,196] {task_command.py:370} INFO - Running <TaskInstance: dags_new_version.processing_user manual__2022-06-20T06:40:52.621468+00:00 [running]> on host ca3ce831c04f
[2022-06-20 06:41:19,852] {taskinstance.py:1571} INFO - Exporting the following env vars:
AIRFLOW_CTX_DAG_OWNER=***
AIRFLOW_CTX_DAG_ID=dags_new_version
AIRFLOW_CTX_TASK_ID=processing_user
AIRFLOW_CTX_EXECUTION_DATE=2022-06-20T06:40:52.621468+00:00
AIRFLOW_CTX_TRY_NUMBER=1
AIRFLOW_CTX_DAG_RUN_ID=manual__2022-06-20T06:40:52.621468+00:00
[2022-06-20 06:41:19,918] {taskinstance.py:1889} ERROR - Task failed with exception
Traceback (most recent call last):
  File "/home/airflow/.local/lib/python3.7/site-packages/airflow/operators/python.py", line 171, in execute
    return_value = self.execute_callable()
  File "/home/airflow/.local/lib/python3.7/site-packages/airflow/operators/python.py", line 189, in execute_callable
    return self.python_callable(*self.op_args, **self.op_kwargs)
  File "/opt/airflow/dags/user.py", line 31, in _processing_user
    processed_user.to_csv('/processed_user.csv', index=None, header=False)
  File "/home/airflow/.local/lib/python3.7/site-packages/pandas/core/generic.py", line 3482, in to_csv
    storage_options=storage_options,
  File "/home/airflow/.local/lib/python3.7/site-packages/pandas/io/formats/format.py", line 1105, in to_csv
    csv_formatter.save()
  File "/home/airflow/.local/lib/python3.7/site-packages/pandas/io/formats/csvs.py", line 243, in save
    storage_options=self.storage_options,
  File "/home/airflow/.local/lib/python3.7/site-packages/pandas/io/common.py", line 707, in get_handle
    newline="",
PermissionError: [Errno 13] Permission denied: '/processed_user.csv'
[2022-06-20 06:41:19,981] {taskinstance.py:1400} INFO - Marking task as UP_FOR_RETRY. dag_id=dags_new_version, task_id=processing_user, execution_date=20220620T064052, start_date=20220620T064116, end_date=20220620T064119
[2022-06-20 06:41:20,088] {standard_task_runner.py:97} ERROR - Failed to execute job 186 for task processing_user ([Errno 13] Permission denied: '/processed_user.csv'; 388)
[2022-06-20 06:41:20,248] {local_task_job.py:156} INFO - Task exited with return code 1
[2022-06-20 06:41:20,536] {local_task_job.py:273} INFO - 0 downstream tasks scheduled from follow-on schedule check
