[2022-06-21 06:40:59,485] {taskinstance.py:1159} INFO - Dependencies all met for <TaskInstance: dags_new_version.is_api_available manual__2022-06-21T06:40:54.217934+00:00 [queued]>
[2022-06-21 06:40:59,510] {taskinstance.py:1159} INFO - Dependencies all met for <TaskInstance: dags_new_version.is_api_available manual__2022-06-21T06:40:54.217934+00:00 [queued]>
[2022-06-21 06:40:59,512] {taskinstance.py:1356} INFO - 
--------------------------------------------------------------------------------
[2022-06-21 06:40:59,514] {taskinstance.py:1357} INFO - Starting attempt 1 of 2
[2022-06-21 06:40:59,525] {taskinstance.py:1358} INFO - 
--------------------------------------------------------------------------------
[2022-06-21 06:40:59,568] {taskinstance.py:1377} INFO - Executing <Task(HttpSensor): is_api_available> on 2022-06-21 06:40:54.217934+00:00
[2022-06-21 06:40:59,629] {standard_task_runner.py:52} INFO - Started process 16955 to run task
[2022-06-21 06:40:59,652] {standard_task_runner.py:79} INFO - Running: ['***', 'tasks', 'run', 'dags_new_version', 'is_api_available', 'manual__2022-06-21T06:40:54.217934+00:00', '--job-id', '219', '--raw', '--subdir', 'DAGS_FOLDER/user.py', '--cfg-path', '/tmp/tmp3nd0v3je', '--error-file', '/tmp/tmpi36wsi0t']
[2022-06-21 06:40:59,681] {standard_task_runner.py:80} INFO - Job 219: Subtask is_api_available
[2022-06-21 06:41:00,162] {task_command.py:370} INFO - Running <TaskInstance: dags_new_version.is_api_available manual__2022-06-21T06:40:54.217934+00:00 [running]> on host ca3ce831c04f
[2022-06-21 06:41:00,700] {taskinstance.py:1571} INFO - Exporting the following env vars:
AIRFLOW_CTX_DAG_OWNER=***
AIRFLOW_CTX_DAG_ID=dags_new_version
AIRFLOW_CTX_TASK_ID=is_api_available
AIRFLOW_CTX_EXECUTION_DATE=2022-06-21T06:40:54.217934+00:00
AIRFLOW_CTX_TRY_NUMBER=1
AIRFLOW_CTX_DAG_RUN_ID=manual__2022-06-21T06:40:54.217934+00:00
[2022-06-21 06:41:00,707] {http.py:97} INFO - Poking: api/
[2022-06-21 06:41:00,807] {base.py:68} INFO - Using connection ID 'user_api' for task execution.
[2022-06-21 06:41:00,811] {http.py:129} INFO - Sending 'GET' to url: https://randomuser.me/api/
[2022-06-21 06:41:05,021] {http.py:142} ERROR - HTTP error: Internal Server Error
[2022-06-21 06:41:05,023] {http.py:143} ERROR - <html>
<head><title>500 Internal Server Error</title></head>
<body bgcolor="white">
<center><h1>500 Internal Server Error</h1></center>
<hr><center>nginx</center>
</body>
</html>

[2022-06-21 06:41:05,051] {taskinstance.py:1889} ERROR - Task failed with exception
Traceback (most recent call last):
  File "/home/airflow/.local/lib/python3.7/site-packages/airflow/providers/http/hooks/http.py", line 140, in check_response
    response.raise_for_status()
  File "/home/airflow/.local/lib/python3.7/site-packages/requests/models.py", line 960, in raise_for_status
    raise HTTPError(http_error_msg, response=self)
requests.exceptions.HTTPError: 500 Server Error: Internal Server Error for url: https://randomuser.me/api/

During handling of the above exception, another exception occurred:

Traceback (most recent call last):
  File "/home/airflow/.local/lib/python3.7/site-packages/airflow/sensors/base.py", line 277, in execute
    poke_return = self.poke(context)
  File "/home/airflow/.local/lib/python3.7/site-packages/airflow/providers/http/sensors/http.py", line 112, in poke
    raise exc
  File "/home/airflow/.local/lib/python3.7/site-packages/airflow/providers/http/sensors/http.py", line 103, in poke
    extra_options=self.extra_options,
  File "/home/airflow/.local/lib/python3.7/site-packages/airflow/providers/http/hooks/http.py", line 130, in run
    return self.run_and_check(session, prepped_request, extra_options)
  File "/home/airflow/.local/lib/python3.7/site-packages/airflow/providers/http/hooks/http.py", line 183, in run_and_check
    self.check_response(response)
  File "/home/airflow/.local/lib/python3.7/site-packages/airflow/providers/http/hooks/http.py", line 144, in check_response
    raise AirflowException(str(response.status_code) + ":" + response.reason)
airflow.exceptions.AirflowException: 500:Internal Server Error
[2022-06-21 06:41:05,061] {taskinstance.py:1400} INFO - Marking task as UP_FOR_RETRY. dag_id=dags_new_version, task_id=is_api_available, execution_date=20220621T064054, start_date=20220621T064059, end_date=20220621T064105
[2022-06-21 06:41:05,091] {standard_task_runner.py:97} ERROR - Failed to execute job 219 for task is_api_available (500:Internal Server Error; 16955)
[2022-06-21 06:41:05,146] {local_task_job.py:156} INFO - Task exited with return code 1
[2022-06-21 06:41:05,220] {local_task_job.py:273} INFO - 0 downstream tasks scheduled from follow-on schedule check
