[2022-06-20 06:34:49,054] {taskinstance.py:1159} INFO - Dependencies all met for <TaskInstance: dags_new_version.create_table scheduled__2022-06-17T00:00:00+00:00 [queued]>
[2022-06-20 06:34:49,698] {taskinstance.py:1159} INFO - Dependencies all met for <TaskInstance: dags_new_version.create_table scheduled__2022-06-17T00:00:00+00:00 [queued]>
[2022-06-20 06:34:49,714] {taskinstance.py:1356} INFO - 
--------------------------------------------------------------------------------
[2022-06-20 06:34:49,731] {taskinstance.py:1357} INFO - Starting attempt 1 of 2
[2022-06-20 06:34:49,752] {taskinstance.py:1358} INFO - 
--------------------------------------------------------------------------------
[2022-06-20 06:34:50,215] {taskinstance.py:1377} INFO - Executing <Task(PostgresOperator): create_table> on 2022-06-17 00:00:00+00:00
[2022-06-20 06:34:50,451] {standard_task_runner.py:52} INFO - Started process 98 to run task
[2022-06-20 06:34:50,549] {standard_task_runner.py:79} INFO - Running: ['***', 'tasks', 'run', 'dags_new_version', 'create_table', 'scheduled__2022-06-17T00:00:00+00:00', '--job-id', '162', '--raw', '--subdir', 'DAGS_FOLDER/user.py', '--cfg-path', '/tmp/tmpa36wrxsn', '--error-file', '/tmp/tmpxox8is4d']
[2022-06-20 06:34:50,558] {standard_task_runner.py:80} INFO - Job 162: Subtask create_table
[2022-06-20 06:34:51,805] {task_command.py:370} INFO - Running <TaskInstance: dags_new_version.create_table scheduled__2022-06-17T00:00:00+00:00 [running]> on host ca3ce831c04f
[2022-06-20 06:34:53,633] {taskinstance.py:1571} INFO - Exporting the following env vars:
AIRFLOW_CTX_DAG_OWNER=***
AIRFLOW_CTX_DAG_ID=dags_new_version
AIRFLOW_CTX_TASK_ID=create_table
AIRFLOW_CTX_EXECUTION_DATE=2022-06-17T00:00:00+00:00
AIRFLOW_CTX_TRY_NUMBER=1
AIRFLOW_CTX_DAG_RUN_ID=scheduled__2022-06-17T00:00:00+00:00
[2022-06-20 06:34:53,926] {base.py:68} INFO - Using connection ID 'postgre_sql' for task execution.
[2022-06-20 06:34:54,003] {taskinstance.py:1889} ERROR - Task failed with exception
Traceback (most recent call last):
  File "/home/airflow/.local/lib/python3.7/site-packages/airflow/providers/postgres/operators/postgres.py", line 92, in execute
    self.hook.run(self.sql, self.autocommit, parameters=self.parameters)
  File "/home/airflow/.local/lib/python3.7/site-packages/airflow/hooks/dbapi.py", line 186, in run
    with closing(self.get_conn()) as conn:
  File "/home/airflow/.local/lib/python3.7/site-packages/airflow/providers/postgres/hooks/postgres.py", line 113, in get_conn
    self.conn = psycopg2.connect(**conn_args)
  File "/home/airflow/.local/lib/python3.7/site-packages/psycopg2/__init__.py", line 122, in connect
    conn = _connect(dsn, connection_factory=connection_factory, **kwasync)
psycopg2.OperationalError: connection to server at "192.168.22.49", port 5432 failed: Connection refused
	Is the server running on that host and accepting TCP/IP connections?

[2022-06-20 06:34:54,508] {taskinstance.py:1400} INFO - Marking task as UP_FOR_RETRY. dag_id=dags_new_version, task_id=create_table, execution_date=20220617T000000, start_date=20220620T063449, end_date=20220620T063454
[2022-06-20 06:34:54,983] {standard_task_runner.py:97} ERROR - Failed to execute job 162 for task create_table (connection to server at "192.168.22.49", port 5432 failed: Connection refused
	Is the server running on that host and accepting TCP/IP connections?
; 98)
[2022-06-20 06:34:55,181] {local_task_job.py:156} INFO - Task exited with return code 1
[2022-06-20 06:34:56,375] {local_task_job.py:273} INFO - 0 downstream tasks scheduled from follow-on schedule check
