[2022-06-17 09:56:57,939] {taskinstance.py:1159} INFO - Dependencies all met for <TaskInstance: dags_new_version.processing_user manual__2022-06-17T09:54:16.978802+00:00 [queued]>
[2022-06-17 09:56:57,958] {taskinstance.py:1159} INFO - Dependencies all met for <TaskInstance: dags_new_version.processing_user manual__2022-06-17T09:54:16.978802+00:00 [queued]>
[2022-06-17 09:56:57,962] {taskinstance.py:1356} INFO - 
--------------------------------------------------------------------------------
[2022-06-17 09:56:57,964] {taskinstance.py:1357} INFO - Starting attempt 2 of 2
[2022-06-17 09:56:57,966] {taskinstance.py:1358} INFO - 
--------------------------------------------------------------------------------
[2022-06-17 09:56:58,001] {taskinstance.py:1377} INFO - Executing <Task(PythonOperator): processing_user> on 2022-06-17 09:54:16.978802+00:00
[2022-06-17 09:56:58,012] {standard_task_runner.py:52} INFO - Started process 5875 to run task
[2022-06-17 09:56:58,029] {standard_task_runner.py:79} INFO - Running: ['***', 'tasks', 'run', 'dags_new_version', 'processing_user', 'manual__2022-06-17T09:54:16.978802+00:00', '--job-id', '147', '--raw', '--subdir', 'DAGS_FOLDER/user.py', '--cfg-path', '/tmp/tmpa9x7_bxq', '--error-file', '/tmp/tmp2f0snyzo']
[2022-06-17 09:56:58,031] {standard_task_runner.py:80} INFO - Job 147: Subtask processing_user
[2022-06-17 09:56:58,185] {task_command.py:370} INFO - Running <TaskInstance: dags_new_version.processing_user manual__2022-06-17T09:54:16.978802+00:00 [running]> on host adccabfb4a32
[2022-06-17 09:56:58,323] {taskinstance.py:1571} INFO - Exporting the following env vars:
AIRFLOW_CTX_DAG_OWNER=***
AIRFLOW_CTX_DAG_ID=dags_new_version
AIRFLOW_CTX_TASK_ID=processing_user
AIRFLOW_CTX_EXECUTION_DATE=2022-06-17T09:54:16.978802+00:00
AIRFLOW_CTX_TRY_NUMBER=2
AIRFLOW_CTX_DAG_RUN_ID=manual__2022-06-17T09:54:16.978802+00:00
[2022-06-17 09:56:58,344] {taskinstance.py:1889} ERROR - Task failed with exception
Traceback (most recent call last):
  File "/home/airflow/.local/lib/python3.7/site-packages/airflow/operators/python.py", line 171, in execute
    return_value = self.execute_callable()
  File "/home/airflow/.local/lib/python3.7/site-packages/airflow/operators/python.py", line 189, in execute_callable
    return self.python_callable(*self.op_args, **self.op_kwargs)
  File "/opt/airflow/dags/user.py", line 20, in _processing_user
    raise ValueError('User is empty..')
ValueError: User is empty..
[2022-06-17 09:56:58,361] {taskinstance.py:1400} INFO - Marking task as FAILED. dag_id=dags_new_version, task_id=processing_user, execution_date=20220617T095416, start_date=20220617T095657, end_date=20220617T095658
[2022-06-17 09:56:58,378] {standard_task_runner.py:97} ERROR - Failed to execute job 147 for task processing_user (User is empty..; 5875)
[2022-06-17 09:56:58,400] {local_task_job.py:156} INFO - Task exited with return code 1
[2022-06-17 09:56:58,447] {local_task_job.py:273} INFO - 0 downstream tasks scheduled from follow-on schedule check
