[2022-06-14 08:02:04,365] {taskinstance.py:1159} INFO - Dependencies all met for <TaskInstance: table_postgres.create_postgres_table manual__2022-06-14T08:02:01.491228+00:00 [queued]>
[2022-06-14 08:02:04,393] {taskinstance.py:1159} INFO - Dependencies all met for <TaskInstance: table_postgres.create_postgres_table manual__2022-06-14T08:02:01.491228+00:00 [queued]>
[2022-06-14 08:02:04,394] {taskinstance.py:1356} INFO - 
--------------------------------------------------------------------------------
[2022-06-14 08:02:04,396] {taskinstance.py:1357} INFO - Starting attempt 1 of 2
[2022-06-14 08:02:04,398] {taskinstance.py:1358} INFO - 
--------------------------------------------------------------------------------
[2022-06-14 08:02:04,427] {taskinstance.py:1377} INFO - Executing <Task(PostgresOperator): create_postgres_table> on 2022-06-14 08:02:01.491228+00:00
[2022-06-14 08:02:04,449] {standard_task_runner.py:79} INFO - Running: ['***', 'tasks', 'run', 'table_postgres', 'create_postgres_table', 'manual__2022-06-14T08:02:01.491228+00:00', '--job-id', '38', '--raw', '--subdir', 'DAGS_FOLDER/create_user.py', '--cfg-path', '/tmp/tmpo0g8s9qh', '--error-file', '/tmp/tmpds4mfjvj']
[2022-06-14 08:02:04,444] {standard_task_runner.py:52} INFO - Started process 1935 to run task
[2022-06-14 08:02:04,458] {standard_task_runner.py:80} INFO - Job 38: Subtask create_postgres_table
[2022-06-14 08:02:04,611] {task_command.py:370} INFO - Running <TaskInstance: table_postgres.create_postgres_table manual__2022-06-14T08:02:01.491228+00:00 [running]> on host 38a912dff3f2
[2022-06-14 08:02:04,973] {taskinstance.py:1571} INFO - Exporting the following env vars:
AIRFLOW_CTX_DAG_OWNER=***
AIRFLOW_CTX_DAG_ID=table_postgres
AIRFLOW_CTX_TASK_ID=create_postgres_table
AIRFLOW_CTX_EXECUTION_DATE=2022-06-14T08:02:01.491228+00:00
AIRFLOW_CTX_TRY_NUMBER=1
AIRFLOW_CTX_DAG_RUN_ID=manual__2022-06-14T08:02:01.491228+00:00
[2022-06-14 08:02:05,084] {base.py:68} INFO - Using connection ID 'postgre_sql' for task execution.
[2022-06-14 08:02:05,098] {taskinstance.py:1889} ERROR - Task failed with exception
Traceback (most recent call last):
  File "/home/airflow/.local/lib/python3.7/site-packages/airflow/providers/postgres/operators/postgres.py", line 92, in execute
    self.hook.run(self.sql, self.autocommit, parameters=self.parameters)
  File "/home/airflow/.local/lib/python3.7/site-packages/airflow/hooks/dbapi.py", line 186, in run
    with closing(self.get_conn()) as conn:
  File "/home/airflow/.local/lib/python3.7/site-packages/airflow/providers/postgres/hooks/postgres.py", line 113, in get_conn
    self.conn = psycopg2.connect(**conn_args)
  File "/home/airflow/.local/lib/python3.7/site-packages/psycopg2/__init__.py", line 122, in connect
    conn = _connect(dsn, connection_factory=connection_factory, **kwasync)
psycopg2.OperationalError: connection to server at "localhost" (127.0.0.1), port 5432 failed: Connection refused
	Is the server running on that host and accepting TCP/IP connections?
connection to server at "localhost" (::1), port 5432 failed: Cannot assign requested address
	Is the server running on that host and accepting TCP/IP connections?

[2022-06-14 08:02:05,212] {taskinstance.py:1400} INFO - Marking task as UP_FOR_RETRY. dag_id=table_postgres, task_id=create_postgres_table, execution_date=20220614T080201, start_date=20220614T080204, end_date=20220614T080205
[2022-06-14 08:02:05,324] {standard_task_runner.py:97} ERROR - Failed to execute job 38 for task create_postgres_table (connection to server at "localhost" (127.0.0.1), port 5432 failed: Connection refused
	Is the server running on that host and accepting TCP/IP connections?
connection to server at "localhost" (::1), port 5432 failed: Cannot assign requested address
	Is the server running on that host and accepting TCP/IP connections?
; 1935)
[2022-06-14 08:02:05,381] {local_task_job.py:156} INFO - Task exited with return code 1
[2022-06-14 08:02:05,699] {local_task_job.py:273} INFO - 0 downstream tasks scheduled from follow-on schedule check
