[2022-06-17 08:23:31,389] {taskinstance.py:1159} INFO - Dependencies all met for <TaskInstance: dags_new_version.create_table scheduled__2022-04-07T00:00:00+00:00 [queued]>
[2022-06-17 08:23:32,152] {taskinstance.py:1159} INFO - Dependencies all met for <TaskInstance: dags_new_version.create_table scheduled__2022-04-07T00:00:00+00:00 [queued]>
[2022-06-17 08:23:32,175] {taskinstance.py:1356} INFO - 
--------------------------------------------------------------------------------
[2022-06-17 08:23:32,193] {taskinstance.py:1357} INFO - Starting attempt 1 of 2
[2022-06-17 08:23:32,202] {taskinstance.py:1358} INFO - 
--------------------------------------------------------------------------------
[2022-06-17 08:23:34,777] {taskinstance.py:1377} INFO - Executing <Task(PostgresOperator): create_table> on 2022-04-07 00:00:00+00:00
[2022-06-17 08:23:35,173] {standard_task_runner.py:52} INFO - Started process 2251 to run task
[2022-06-17 08:23:35,800] {standard_task_runner.py:79} INFO - Running: ['***', 'tasks', 'run', 'dags_new_version', 'create_table', 'scheduled__2022-04-07T00:00:00+00:00', '--job-id', '102', '--raw', '--subdir', 'DAGS_FOLDER/user.py', '--cfg-path', '/tmp/tmpgegpx4hi', '--error-file', '/tmp/tmp7954hszd']
[2022-06-17 08:23:35,921] {standard_task_runner.py:80} INFO - Job 102: Subtask create_table
[2022-06-17 08:23:42,192] {task_command.py:370} INFO - Running <TaskInstance: dags_new_version.create_table scheduled__2022-04-07T00:00:00+00:00 [running]> on host adccabfb4a32
[2022-06-17 08:23:45,411] {taskinstance.py:1571} INFO - Exporting the following env vars:
AIRFLOW_CTX_DAG_OWNER=***
AIRFLOW_CTX_DAG_ID=dags_new_version
AIRFLOW_CTX_TASK_ID=create_table
AIRFLOW_CTX_EXECUTION_DATE=2022-04-07T00:00:00+00:00
AIRFLOW_CTX_TRY_NUMBER=1
AIRFLOW_CTX_DAG_RUN_ID=scheduled__2022-04-07T00:00:00+00:00
[2022-06-17 08:23:45,606] {base.py:68} INFO - Using connection ID 'postgre_sql' for task execution.
[2022-06-17 08:25:00,661] {taskinstance.py:1889} ERROR - Task failed with exception
Traceback (most recent call last):
  File "/home/airflow/.local/lib/python3.7/site-packages/airflow/providers/postgres/operators/postgres.py", line 92, in execute
    self.hook.run(self.sql, self.autocommit, parameters=self.parameters)
  File "/home/airflow/.local/lib/python3.7/site-packages/airflow/hooks/dbapi.py", line 186, in run
    with closing(self.get_conn()) as conn:
  File "/home/airflow/.local/lib/python3.7/site-packages/airflow/providers/postgres/hooks/postgres.py", line 113, in get_conn
    self.conn = psycopg2.connect(**conn_args)
  File "/home/airflow/.local/lib/python3.7/site-packages/psycopg2/__init__.py", line 122, in connect
    conn = _connect(dsn, connection_factory=connection_factory, **kwasync)
psycopg2.OperationalError: connection to server at "192.168.22.37", port 5432 failed: Connection refused
	Is the server running on that host and accepting TCP/IP connections?

[2022-06-17 08:25:00,725] {taskinstance.py:1400} INFO - Marking task as UP_FOR_RETRY. dag_id=dags_new_version, task_id=create_table, execution_date=20220407T000000, start_date=20220617T082331, end_date=20220617T082500
[2022-06-17 08:25:01,166] {standard_task_runner.py:97} ERROR - Failed to execute job 102 for task create_table (connection to server at "192.168.22.37", port 5432 failed: Connection refused
	Is the server running on that host and accepting TCP/IP connections?
; 2251)
[2022-06-17 08:25:01,236] {local_task_job.py:156} INFO - Task exited with return code 1
[2022-06-17 08:25:01,313] {local_task_job.py:273} INFO - 0 downstream tasks scheduled from follow-on schedule check
