[2022-06-20 06:37:20,292] {taskinstance.py:1159} INFO - Dependencies all met for <TaskInstance: dags_new_version.processing_user scheduled__2022-06-19T00:00:00+00:00 [queued]>
[2022-06-20 06:37:20,356] {taskinstance.py:1159} INFO - Dependencies all met for <TaskInstance: dags_new_version.processing_user scheduled__2022-06-19T00:00:00+00:00 [queued]>
[2022-06-20 06:37:20,359] {taskinstance.py:1356} INFO - 
--------------------------------------------------------------------------------
[2022-06-20 06:37:20,360] {taskinstance.py:1357} INFO - Starting attempt 1 of 2
[2022-06-20 06:37:20,363] {taskinstance.py:1358} INFO - 
--------------------------------------------------------------------------------
[2022-06-20 06:37:20,442] {taskinstance.py:1377} INFO - Executing <Task(PythonOperator): processing_user> on 2022-06-19 00:00:00+00:00
[2022-06-20 06:37:20,496] {standard_task_runner.py:52} INFO - Started process 219 to run task
[2022-06-20 06:37:20,576] {standard_task_runner.py:79} INFO - Running: ['***', 'tasks', 'run', 'dags_new_version', 'processing_user', 'scheduled__2022-06-19T00:00:00+00:00', '--job-id', '175', '--raw', '--subdir', 'DAGS_FOLDER/user.py', '--cfg-path', '/tmp/tmp69v0o9_u', '--error-file', '/tmp/tmprzaa9umj']
[2022-06-20 06:37:20,583] {standard_task_runner.py:80} INFO - Job 175: Subtask processing_user
[2022-06-20 06:37:20,849] {task_command.py:370} INFO - Running <TaskInstance: dags_new_version.processing_user scheduled__2022-06-19T00:00:00+00:00 [running]> on host ca3ce831c04f
[2022-06-20 06:37:21,335] {taskinstance.py:1571} INFO - Exporting the following env vars:
AIRFLOW_CTX_DAG_OWNER=***
AIRFLOW_CTX_DAG_ID=dags_new_version
AIRFLOW_CTX_TASK_ID=processing_user
AIRFLOW_CTX_EXECUTION_DATE=2022-06-19T00:00:00+00:00
AIRFLOW_CTX_TRY_NUMBER=1
AIRFLOW_CTX_DAG_RUN_ID=scheduled__2022-06-19T00:00:00+00:00
[2022-06-20 06:37:21,466] {taskinstance.py:1889} ERROR - Task failed with exception
Traceback (most recent call last):
  File "/home/airflow/.local/lib/python3.7/site-packages/airflow/operators/python.py", line 171, in execute
    return_value = self.execute_callable()
  File "/home/airflow/.local/lib/python3.7/site-packages/airflow/operators/python.py", line 189, in execute_callable
    return self.python_callable(*self.op_args, **self.op_kwargs)
  File "/opt/airflow/dags/user.py", line 31, in _processing_user
    processed_user.to_csv('/processed_user.csv', index=None, header=False)
  File "/home/airflow/.local/lib/python3.7/site-packages/pandas/core/generic.py", line 3482, in to_csv
    storage_options=storage_options,
  File "/home/airflow/.local/lib/python3.7/site-packages/pandas/io/formats/format.py", line 1105, in to_csv
    csv_formatter.save()
  File "/home/airflow/.local/lib/python3.7/site-packages/pandas/io/formats/csvs.py", line 243, in save
    storage_options=self.storage_options,
  File "/home/airflow/.local/lib/python3.7/site-packages/pandas/io/common.py", line 707, in get_handle
    newline="",
PermissionError: [Errno 13] Permission denied: '/processed_user.csv'
[2022-06-20 06:37:21,540] {taskinstance.py:1400} INFO - Marking task as UP_FOR_RETRY. dag_id=dags_new_version, task_id=processing_user, execution_date=20220619T000000, start_date=20220620T063720, end_date=20220620T063721
[2022-06-20 06:37:21,679] {standard_task_runner.py:97} ERROR - Failed to execute job 175 for task processing_user ([Errno 13] Permission denied: '/processed_user.csv'; 219)
[2022-06-20 06:37:21,801] {local_task_job.py:156} INFO - Task exited with return code 1
[2022-06-20 06:37:21,949] {local_task_job.py:273} INFO - 0 downstream tasks scheduled from follow-on schedule check
