[2022-06-17 10:06:50,025] {taskinstance.py:1159} INFO - Dependencies all met for <TaskInstance: dags_new_version.processing_user manual__2022-06-17T09:42:18.403920+00:00 [queued]>
[2022-06-17 10:06:50,064] {taskinstance.py:1159} INFO - Dependencies all met for <TaskInstance: dags_new_version.processing_user manual__2022-06-17T09:42:18.403920+00:00 [queued]>
[2022-06-17 10:06:50,068] {taskinstance.py:1356} INFO - 
--------------------------------------------------------------------------------
[2022-06-17 10:06:50,070] {taskinstance.py:1357} INFO - Starting attempt 3 of 4
[2022-06-17 10:06:50,072] {taskinstance.py:1358} INFO - 
--------------------------------------------------------------------------------
[2022-06-17 10:06:50,119] {taskinstance.py:1377} INFO - Executing <Task(PythonOperator): processing_user> on 2022-06-17 09:42:18.403920+00:00
[2022-06-17 10:06:50,135] {standard_task_runner.py:52} INFO - Started process 6276 to run task
[2022-06-17 10:06:50,170] {standard_task_runner.py:79} INFO - Running: ['***', 'tasks', 'run', 'dags_new_version', 'processing_user', 'manual__2022-06-17T09:42:18.403920+00:00', '--job-id', '152', '--raw', '--subdir', 'DAGS_FOLDER/user.py', '--cfg-path', '/tmp/tmpufuz8vva', '--error-file', '/tmp/tmp6zzfbgxj']
[2022-06-17 10:06:50,203] {standard_task_runner.py:80} INFO - Job 152: Subtask processing_user
[2022-06-17 10:06:50,423] {task_command.py:370} INFO - Running <TaskInstance: dags_new_version.processing_user manual__2022-06-17T09:42:18.403920+00:00 [running]> on host adccabfb4a32
[2022-06-17 10:06:50,660] {taskinstance.py:1571} INFO - Exporting the following env vars:
AIRFLOW_CTX_DAG_OWNER=***
AIRFLOW_CTX_DAG_ID=dags_new_version
AIRFLOW_CTX_TASK_ID=processing_user
AIRFLOW_CTX_EXECUTION_DATE=2022-06-17T09:42:18.403920+00:00
AIRFLOW_CTX_TRY_NUMBER=3
AIRFLOW_CTX_DAG_RUN_ID=manual__2022-06-17T09:42:18.403920+00:00
[2022-06-17 10:06:50,699] {taskinstance.py:1889} ERROR - Task failed with exception
Traceback (most recent call last):
  File "/home/airflow/.local/lib/python3.7/site-packages/airflow/operators/python.py", line 171, in execute
    return_value = self.execute_callable()
  File "/home/airflow/.local/lib/python3.7/site-packages/airflow/operators/python.py", line 189, in execute_callable
    return self.python_callable(*self.op_args, **self.op_kwargs)
  File "/opt/airflow/dags/user.py", line 31, in _processing_user
    processed_user.to_csv('/processed_user.csv', index=None, header=False)
  File "/home/airflow/.local/lib/python3.7/site-packages/pandas/core/generic.py", line 3482, in to_csv
    storage_options=storage_options,
  File "/home/airflow/.local/lib/python3.7/site-packages/pandas/io/formats/format.py", line 1105, in to_csv
    csv_formatter.save()
  File "/home/airflow/.local/lib/python3.7/site-packages/pandas/io/formats/csvs.py", line 243, in save
    storage_options=self.storage_options,
  File "/home/airflow/.local/lib/python3.7/site-packages/pandas/io/common.py", line 707, in get_handle
    newline="",
PermissionError: [Errno 13] Permission denied: '/processed_user.csv'
[2022-06-17 10:06:50,737] {taskinstance.py:1400} INFO - Marking task as UP_FOR_RETRY. dag_id=dags_new_version, task_id=processing_user, execution_date=20220617T094218, start_date=20220617T100650, end_date=20220617T100650
[2022-06-17 10:06:50,772] {standard_task_runner.py:97} ERROR - Failed to execute job 152 for task processing_user ([Errno 13] Permission denied: '/processed_user.csv'; 6276)
[2022-06-17 10:06:50,827] {local_task_job.py:156} INFO - Task exited with return code 1
[2022-06-17 10:06:50,920] {local_task_job.py:273} INFO - 0 downstream tasks scheduled from follow-on schedule check
