[2022-06-14 08:16:09,554] {taskinstance.py:1159} INFO - Dependencies all met for <TaskInstance: table_postgres.create_postgres_table manual__2022-06-14T08:13:57.559420+00:00 [queued]>
[2022-06-14 08:16:09,623] {taskinstance.py:1159} INFO - Dependencies all met for <TaskInstance: table_postgres.create_postgres_table manual__2022-06-14T08:13:57.559420+00:00 [queued]>
[2022-06-14 08:16:09,625] {taskinstance.py:1356} INFO - 
--------------------------------------------------------------------------------
[2022-06-14 08:16:09,629] {taskinstance.py:1357} INFO - Starting attempt 2 of 2
[2022-06-14 08:16:09,632] {taskinstance.py:1358} INFO - 
--------------------------------------------------------------------------------
[2022-06-14 08:16:09,699] {taskinstance.py:1377} INFO - Executing <Task(PostgresOperator): create_postgres_table> on 2022-06-14 08:13:57.559420+00:00
[2022-06-14 08:16:09,721] {standard_task_runner.py:52} INFO - Started process 2468 to run task
[2022-06-14 08:16:09,743] {standard_task_runner.py:79} INFO - Running: ['***', 'tasks', 'run', 'table_postgres', 'create_postgres_table', 'manual__2022-06-14T08:13:57.559420+00:00', '--job-id', '52', '--raw', '--subdir', 'DAGS_FOLDER/create_user.py', '--cfg-path', '/tmp/tmpwln9lkkf', '--error-file', '/tmp/tmpa2wphsxa']
[2022-06-14 08:16:09,750] {standard_task_runner.py:80} INFO - Job 52: Subtask create_postgres_table
[2022-06-14 08:16:10,124] {task_command.py:370} INFO - Running <TaskInstance: table_postgres.create_postgres_table manual__2022-06-14T08:13:57.559420+00:00 [running]> on host 38a912dff3f2
[2022-06-14 08:16:10,443] {taskinstance.py:1571} INFO - Exporting the following env vars:
AIRFLOW_CTX_DAG_OWNER=***
AIRFLOW_CTX_DAG_ID=table_postgres
AIRFLOW_CTX_TASK_ID=create_postgres_table
AIRFLOW_CTX_EXECUTION_DATE=2022-06-14T08:13:57.559420+00:00
AIRFLOW_CTX_TRY_NUMBER=2
AIRFLOW_CTX_DAG_RUN_ID=manual__2022-06-14T08:13:57.559420+00:00
[2022-06-14 08:16:10,515] {base.py:68} INFO - Using connection ID 'postgre_sql' for task execution.
[2022-06-14 08:16:10,522] {taskinstance.py:1889} ERROR - Task failed with exception
Traceback (most recent call last):
  File "/home/airflow/.local/lib/python3.7/site-packages/airflow/providers/postgres/operators/postgres.py", line 92, in execute
    self.hook.run(self.sql, self.autocommit, parameters=self.parameters)
  File "/home/airflow/.local/lib/python3.7/site-packages/airflow/hooks/dbapi.py", line 186, in run
    with closing(self.get_conn()) as conn:
  File "/home/airflow/.local/lib/python3.7/site-packages/airflow/providers/postgres/hooks/postgres.py", line 113, in get_conn
    self.conn = psycopg2.connect(**conn_args)
  File "/home/airflow/.local/lib/python3.7/site-packages/psycopg2/__init__.py", line 122, in connect
    conn = _connect(dsn, connection_factory=connection_factory, **kwasync)
psycopg2.OperationalError: connection to server at "localhost" (127.0.0.1), port 5432 failed: Connection refused
	Is the server running on that host and accepting TCP/IP connections?
connection to server at "localhost" (::1), port 5432 failed: Cannot assign requested address
	Is the server running on that host and accepting TCP/IP connections?

[2022-06-14 08:16:10,604] {taskinstance.py:1400} INFO - Marking task as FAILED. dag_id=table_postgres, task_id=create_postgres_table, execution_date=20220614T081357, start_date=20220614T081609, end_date=20220614T081610
[2022-06-14 08:16:10,726] {standard_task_runner.py:97} ERROR - Failed to execute job 52 for task create_postgres_table (connection to server at "localhost" (127.0.0.1), port 5432 failed: Connection refused
	Is the server running on that host and accepting TCP/IP connections?
connection to server at "localhost" (::1), port 5432 failed: Cannot assign requested address
	Is the server running on that host and accepting TCP/IP connections?
; 2468)
[2022-06-14 08:16:10,829] {local_task_job.py:156} INFO - Task exited with return code 1
[2022-06-14 08:16:11,045] {local_task_job.py:273} INFO - 0 downstream tasks scheduled from follow-on schedule check
