[2022-06-17 09:31:24,543] {taskinstance.py:1159} INFO - Dependencies all met for <TaskInstance: dags_new_version.processing_user manual__2022-06-17T09:28:58.145633+00:00 [queued]>
[2022-06-17 09:31:24,576] {taskinstance.py:1159} INFO - Dependencies all met for <TaskInstance: dags_new_version.processing_user manual__2022-06-17T09:28:58.145633+00:00 [queued]>
[2022-06-17 09:31:24,577] {taskinstance.py:1356} INFO - 
--------------------------------------------------------------------------------
[2022-06-17 09:31:24,578] {taskinstance.py:1357} INFO - Starting attempt 2 of 2
[2022-06-17 09:31:24,580] {taskinstance.py:1358} INFO - 
--------------------------------------------------------------------------------
[2022-06-17 09:31:24,627] {taskinstance.py:1377} INFO - Executing <Task(PythonOperator): processing_user> on 2022-06-17 09:28:58.145633+00:00
[2022-06-17 09:31:24,653] {standard_task_runner.py:52} INFO - Started process 4848 to run task
[2022-06-17 09:31:24,669] {standard_task_runner.py:79} INFO - Running: ['***', 'tasks', 'run', 'dags_new_version', 'processing_user', 'manual__2022-06-17T09:28:58.145633+00:00', '--job-id', '128', '--raw', '--subdir', 'DAGS_FOLDER/user.py', '--cfg-path', '/tmp/tmpq4n7fbx1', '--error-file', '/tmp/tmp4jjw7quo']
[2022-06-17 09:31:24,675] {standard_task_runner.py:80} INFO - Job 128: Subtask processing_user
[2022-06-17 09:31:24,962] {task_command.py:370} INFO - Running <TaskInstance: dags_new_version.processing_user manual__2022-06-17T09:28:58.145633+00:00 [running]> on host adccabfb4a32
[2022-06-17 09:31:25,238] {taskinstance.py:1571} INFO - Exporting the following env vars:
AIRFLOW_CTX_DAG_OWNER=***
AIRFLOW_CTX_DAG_ID=dags_new_version
AIRFLOW_CTX_TASK_ID=processing_user
AIRFLOW_CTX_EXECUTION_DATE=2022-06-17T09:28:58.145633+00:00
AIRFLOW_CTX_TRY_NUMBER=2
AIRFLOW_CTX_DAG_RUN_ID=manual__2022-06-17T09:28:58.145633+00:00
[2022-06-17 09:31:25,302] {taskinstance.py:1889} ERROR - Task failed with exception
Traceback (most recent call last):
  File "/home/airflow/.local/lib/python3.7/site-packages/airflow/operators/python.py", line 171, in execute
    return_value = self.execute_callable()
  File "/home/airflow/.local/lib/python3.7/site-packages/airflow/operators/python.py", line 189, in execute_callable
    return self.python_callable(*self.op_args, **self.op_kwargs)
  File "/opt/airflow/dags/user.py", line 20, in _processing_user
    raise ValueError('User is empty..')
ValueError: User is empty..
[2022-06-17 09:31:25,403] {taskinstance.py:1400} INFO - Marking task as FAILED. dag_id=dags_new_version, task_id=processing_user, execution_date=20220617T092858, start_date=20220617T093124, end_date=20220617T093125
[2022-06-17 09:31:25,480] {standard_task_runner.py:97} ERROR - Failed to execute job 128 for task processing_user (User is empty..; 4848)
[2022-06-17 09:31:25,597] {local_task_job.py:156} INFO - Task exited with return code 1
[2022-06-17 09:31:25,791] {local_task_job.py:273} INFO - 0 downstream tasks scheduled from follow-on schedule check
