[2022-06-14 07:48:23,192] {taskinstance.py:1159} INFO - Dependencies all met for <TaskInstance: table_postgres.create_postgres_table manual__2022-06-14T07:48:19.044665+00:00 [queued]>
[2022-06-14 07:48:23,227] {taskinstance.py:1159} INFO - Dependencies all met for <TaskInstance: table_postgres.create_postgres_table manual__2022-06-14T07:48:19.044665+00:00 [queued]>
[2022-06-14 07:48:23,229] {taskinstance.py:1356} INFO - 
--------------------------------------------------------------------------------
[2022-06-14 07:48:23,232] {taskinstance.py:1357} INFO - Starting attempt 1 of 2
[2022-06-14 07:48:23,234] {taskinstance.py:1358} INFO - 
--------------------------------------------------------------------------------
[2022-06-14 07:48:23,271] {taskinstance.py:1377} INFO - Executing <Task(PostgresOperator): create_postgres_table> on 2022-06-14 07:48:19.044665+00:00
[2022-06-14 07:48:23,292] {standard_task_runner.py:52} INFO - Started process 1442 to run task
[2022-06-14 07:48:23,329] {standard_task_runner.py:79} INFO - Running: ['***', 'tasks', 'run', 'table_postgres', 'create_postgres_table', 'manual__2022-06-14T07:48:19.044665+00:00', '--job-id', '34', '--raw', '--subdir', 'DAGS_FOLDER/create_user.py', '--cfg-path', '/tmp/tmpldbuxmh3', '--error-file', '/tmp/tmpytjfekf8']
[2022-06-14 07:48:23,333] {standard_task_runner.py:80} INFO - Job 34: Subtask create_postgres_table
[2022-06-14 07:48:23,582] {task_command.py:370} INFO - Running <TaskInstance: table_postgres.create_postgres_table manual__2022-06-14T07:48:19.044665+00:00 [running]> on host 38a912dff3f2
[2022-06-14 07:48:24,058] {taskinstance.py:1571} INFO - Exporting the following env vars:
AIRFLOW_CTX_DAG_OWNER=***
AIRFLOW_CTX_DAG_ID=table_postgres
AIRFLOW_CTX_TASK_ID=create_postgres_table
AIRFLOW_CTX_EXECUTION_DATE=2022-06-14T07:48:19.044665+00:00
AIRFLOW_CTX_TRY_NUMBER=1
AIRFLOW_CTX_DAG_RUN_ID=manual__2022-06-14T07:48:19.044665+00:00
[2022-06-14 07:48:24,163] {base.py:68} INFO - Using connection ID 'postgre_sql' for task execution.
[2022-06-14 07:48:34,192] {taskinstance.py:1889} ERROR - Task failed with exception
Traceback (most recent call last):
  File "/home/airflow/.local/lib/python3.7/site-packages/airflow/providers/postgres/operators/postgres.py", line 92, in execute
    self.hook.run(self.sql, self.autocommit, parameters=self.parameters)
  File "/home/airflow/.local/lib/python3.7/site-packages/airflow/hooks/dbapi.py", line 186, in run
    with closing(self.get_conn()) as conn:
  File "/home/airflow/.local/lib/python3.7/site-packages/airflow/providers/postgres/hooks/postgres.py", line 113, in get_conn
    self.conn = psycopg2.connect(**conn_args)
  File "/home/airflow/.local/lib/python3.7/site-packages/psycopg2/__init__.py", line 122, in connect
    conn = _connect(dsn, connection_factory=connection_factory, **kwasync)
psycopg2.OperationalError: could not translate host name "host.docker.local" to address: Temporary failure in name resolution

[2022-06-14 07:48:34,207] {taskinstance.py:1400} INFO - Marking task as UP_FOR_RETRY. dag_id=table_postgres, task_id=create_postgres_table, execution_date=20220614T074819, start_date=20220614T074823, end_date=20220614T074834
[2022-06-14 07:48:34,233] {standard_task_runner.py:97} ERROR - Failed to execute job 34 for task create_postgres_table (could not translate host name "host.docker.local" to address: Temporary failure in name resolution
; 1442)
[2022-06-14 07:48:34,267] {local_task_job.py:156} INFO - Task exited with return code 1
[2022-06-14 07:48:34,337] {local_task_job.py:273} INFO - 0 downstream tasks scheduled from follow-on schedule check
